<?xml version="1.0"?>
<robot name="rr_robot">

    <!-- 基座 -->
    <link name="base">
        <visual>
            <geometry>
                <cylinder radius="0.1" length="0.05"/>
            </geometry>
            <material name="base_mat">
                <color rgba="0.3 0.3 0.3 1"/>
            </material>
        </visual>
        <collision>
            <geometry>
                <cylinder radius="0.1" length="0.05"/>
            </geometry>
        </collision>
        <inertial>
            <mass value="1.0"/>
            <inertia ixx="0.1" ixy="0" ixz="0" iyy="0.1" iyz="0" izz="0.1"/>
        </inertial>
    </link>

    <!-- 第一个连杆 -->
    <link name="link1">
        <visual>
            <geometry>
                <box size="0.05 0.05 0.5"/>
            </geometry>
            <origin xyz="0 0 0.25"/>
            <material name="link1_mat">
                <color rgba="0.7 0.7 0.7 1"/>
            </material>
        </visual>
        <collision>
            <geometry>
                <box size="0.05 0.05 0.5"/>
            </geometry>
            <origin xyz="0 0 0.25"/>
        </collision>
        <inertial>
            <mass value="1.0"/>
            <origin xyz="0 0 0.25"/>
            <inertia ixx="0.1" ixy="0" ixz="0" iyy="0.1" iyz="0" izz="0.1"/>
        </inertial>
    </link>

    <!-- 第二个连杆 -->
    <link name="link2">
        <visual>
            <geometry>
                <box size="0.05 0.05 0.5"/>
            </geometry>
            <origin xyz="0 0 0.25"/>
            <material name="link2_mat">
                <color rgba="0.5 0.5 0.5 1"/>
            </material>
        </visual>
        <collision>
            <geometry>
                <box size="0.05 0.05 0.5"/>
            </geometry>
            <origin xyz="0 0 0.25"/>
        </collision>
        <inertial>
            <mass value="1.0"/>
            <origin xyz="0 0 0.25"/>
            <inertia ixx="0.1" ixy="0" ixz="0" iyy="0.1" iyz="0" izz="0.1"/>
        </inertial>
    </link>

    <!-- 末端执行器 -->
    <link name="eef">
        <visual>
            <geometry>
                <sphere radius="0.02"/>
            </geometry>
            <material name="eef_mat">
                <color rgba="1 0 0 1"/>
            </material>
        </visual>
        <collision>
            <geometry>
                <sphere radius="0.02"/>
            </geometry>
        </collision>
        <inertial>
            <mass value="0.1"/>
            <inertia ixx="0.001" ixy="0" ixz="0" iyy="0.001" iyz="0" izz="0.001"/>
        </inertial>
    </link>

    <!-- 基座到第一个连杆的关节 -->
    <joint name="base_to_link1" type="continuous">
        <parent link="base"/>
        <child link="link1"/>
        <origin xyz="0 0 0.025"/>
        <axis xyz="1 0 0"/>
        <limit effort="1000.0" velocity="8"/>
    </joint>

    <!-- 第一个连杆到第二个连杆的关节 -->
    <joint name="link1_to_link2" type="continuous">
        <parent link="link1"/>
        <child link="link2"/>
        <origin xyz="0 0 0.5"/>
        <axis xyz="1 0 0"/>
        <limit effort="1000.0" velocity="8"/>
    </joint>

    <!-- 第二个连杆到末端执行器的关节 -->
    <joint name="link2_to_eef" type="fixed">
        <parent link="link2"/>
        <child link="eef"/>
        <origin xyz="0 0 0.5"/>
    </joint>

</robot>